Workbook

Sheet INSTRUCCIONES
A1: PLANTILLA OFICIAL – RENDICIÓN DE CUENTAS (CAPTURA DE AVANCES 2024–2025)
A3: Objetivo | B3: Consolidar avances físicos, financieros y evidencias por meta del Plan de Desarrollo. Esta plantilla alimenta el informe y la plataforma de rendición.
A5: Qué diligenciar | B5: ÚNICAMENTE la hoja 'REGISTRO_AVANCES'. No modificar estructuras, listas ni la hoja 'PLAN_DESARROLLO'.
A7: Reglas | B7: 1) Un registro = una meta (ID_META) en un año. 2) Seleccione ID_META desde la lista (NO escribir a mano). 3) Adjunte evidencia: indique tipo y nombre de archivo/ruta. 4) Los porcentajes y cálculos se llenan automáticamente. 5) Si un campo no aplica, deje en blanco y explique en Observaciones.
A9: Campos obligatorios mínimos | B9: Año, Secretaría, ID_META, Avance ejecutado (si aplica), Presupuesto ejecutado (si aplica), Estado, Evidencia (tipo + archivo/ruta), Responsable.
A11: Fecha de corte | B11: Definir por la Alcaldía (ej.: 31/12/2025).

Sheet PLAN_DESARROLLO
A1: ID_META | B1: BPIM | C1: EJE | D1: SECTOR | E1: META_PRODUCTO | F1: META_CUATRIENIO | G1: OBS_PLAN
A2: META-001 | B2: 2024257770003 | C2: POR EL SUPATÁ SOÑADO AVANZAMOS JUNTOS EN LA LÍNEA ESTRATÉGICA SOCIAL | D2: EDUCACION | E2: Garantizar el 100% de transporte escolar de estudiantes que su institución educativa más cercana supere los 3 kilómetros de distancia desde la vivienda.
A3: META-002 | B3: 2024257770003 | C3: POR EL SUPATÁ SOÑADO AVANZAMOS JUNTOS EN LA LÍNEA ESTRATÉGICA SOCIAL | D3: EDUCACION | E3: Garantizar la gratuidad en la educación en el 100% de las Instituciones y sedes Educativas del municipio.
A4: META-003 | B4: 2024257770003 | C4: POR EL SUPATÁ SOÑADO AVANZAMOS JUNTOS EN LA LÍNEA ESTRATÉGICA SOCIAL | D4: EDUCACION | E4: Mantener la cobertura al 100% y fortalecer el servicio de los estudiantes con el servicio de alimentación escolar
A5: META-004 | B5: 2024257770003 | C5: POR EL SUPATÁ SOÑADO AVANZAMOS JUNTOS EN LA LÍNEA ESTRATÉGICA SOCIAL | D5: EDUCACION | E5: Fortalecer una estrategia extra curricular en fomento del idioma ingles
A6: META-005 | B6: 2024257770004 | C6: POR EL SUPATÁ SOÑADO AVANZAMOS JUNTOS EN LA LÍNEA ESTRATÉGICA SOCIAL | D6: EDUCACION | E6: Realizar 1 dotación de menaje en restaurante escolar de las diferentes sedes de las instituciones Nuestra Señora de la Salud y el Imparal.)
A7: META-006 | B7: 2024257770004 | C7: POR EL SUPATÁ SOÑADO AVANZAMOS JUNTOS EN LA LÍNEA ESTRATÉGICA SOCIAL | D7: EDUCACION | E7: Mejoramiento y/o mantenimiento en infraestructura de las instituciones educativas y sus sedes.
A8: META-007 | B8: 2024257770005 | C8: POR EL SUPATÁ SOÑADO AVANZAMOS JUNTOS EN LA LÍNEA ESTRATÉGICA SOCIAL | D8: EDUCACION | E8: Construir 1 Alianza con SENA o instituciones de Educación Superior para oferta educativa
A9: META-008 | B9: 2024257770005 | C9: POR EL SUPATÁ SOÑADO AVANZAMOS JUNTOS EN LA LÍNEA ESTRATÉGICA SOCIAL | D9: EDUCACION | E9: Realizar un (1) convenio anual con el Servicio Nacional de Aprendizaje –SENA-, para la implementación del Programa de Jóvenes Rurales (SENA Emprende Rural)
A10: META-009 | B10: 2024257770005 | C10: POR EL SUPATÁ SOÑADO AVANZAMOS JUNTOS EN LA LÍNEA ESTRATÉGICA SOCIAL | D10: EDUCACION | E10: Desarrollo de programa de mejoramiento de la calidad educativa PROMCE en minimo dos de sus componentes
A11: META-010 | B11: 2024257770006 | C11: POR EL SUPATÁ SOÑADO AVANZAMOS JUNTOS EN LA LÍNEA ESTRATÉGICA SOCIAL | D11: SALUD | E11: Aumentar al 90% la población beneficiada con la Estrategia de APS Municipal
A12: META-011 | B12: 2024257770006 | C12: POR EL SUPATÁ SOÑADO AVANZAMOS JUNTOS EN LA LÍNEA ESTRATÉGICA SOCIAL | D12: SALUD | E12: Implementar un plan de acción de Participación Social en Salud del Departamento
A13: META-012 | B13: 2024257770006 | C13: POR EL SUPATÁ SOÑADO AVANZAMOS JUNTOS EN LA LÍNEA ESTRATÉGICA SOCIAL | D13: SALUD | E13: Gestionar la realizacion de jornadas de salud en la zona rural del municipio para el fortalecimiento de la atencion en el Nivel Primario, aplicacion de tamizajes y acciones de informacion, que incidan en el mantenimiento de la salud y la deteccion oportuna del riego de enfermedades en la poblacion.
... A56: META-055 | B56: 2024257770012 | C56: POR EL SUPATÁ SOÑADO AVANZAMOS JUNTOS EN LA LÍNEA ESTRATÉGICA SOCIAL | D56: POBLACIÓN VULNERABLE - CAPITULO PRIMERA INFANCIA, INFANCIA, ADOLESCENCIA Y JUVENTUD | E56: Realizar cuatro (4) campañas de prevencion de embarazado en mujeres adolescentes
A57: META-056 | B57: 2024257770012 | C57: POR EL SUPATÁ SOÑADO AVANZAMOS JUNTOS EN LA LÍNEA ESTRATÉGICA SOCIAL | D57: POBLACIÓN VULNERABLE - CAPITULO PRIMERA INFANCIA, INFANCIA, ADOLESCENCIA Y JUVENTUD
A58: META-057 | B58: 2024257770012 | C58: POR EL SUPATÁ SOÑADO AVANZAMOS JUNTOS EN LA LÍNEA ESTRATÉGICA SOCIAL | D58: POBLACIÓN VULNERABLE - CAPITULO PRIMERA INFANCIA, INFANCIA, ADOLESCENCIA Y JUVENTUD | E58: Realizar cuatro (4) talleres en reconocimiento de los derechos de niños, niñas y adolescentes
A59: META-058 | B59: 2024257770012 | C59: POR EL SUPATÁ SOÑADO AVANZAMOS JUNTOS EN LA LÍNEA ESTRATÉGICA SOCIAL | D59: POBLACIÓN VULNERABLE - CAPITULO PRIMERA INFANCIA, INFANCIA, ADOLESCENCIA Y JUVENTUD | E59: Realizar cuatro (4) campañas para la proteccioón y prevención del maltrato infantil
A60: META-059 | B60: 2024257770012 | C60: POR EL SUPATÁ SOÑADO AVANZAMOS JUNTOS EN LA LÍNEA ESTRATÉGICA SOCIAL | D60: POBLACIÓN VULNERABLE - CAPITULO PRIMERA INFANCIA, INFANCIA, ADOLESCENCIA Y JUVENTUD | E60: Realizar dotacion en material pedagógico para los programas de atención de primera infancia
A61: META-060 | B61: 2024257770012 | C61: POR EL SUPATÁ SOÑADO AVANZAMOS JUNTOS EN LA LÍNEA ESTRATÉGICA SOCIAL | D61: POBLACIÓN VULNERABLE - CAPITULO PRIMERA INFANCIA, INFANCIA, ADOLESCENCIA Y JUVENTUD | E61: Realizar cuatro (4) campañas para el fortalecimiento familiar en el municipio
A62: META-061 | B62: 2024257770012 | C62: POR EL SUPATÁ SOÑADO AVANZAMOS JUNTOS EN LA LÍNEA ESTRATÉGICA SOCIAL | D62: POBLACIÓN VULNERABLE - CAPITULO PRIMERA INFANCIA, INFANCIA, ADOLESCENCIA Y JUVENTUD | E62: Realizar las acciones necesarias para el aumento de 1 unidad o cupos en la atención del programa “Educación Rural Dispersa”. (VERIFICAR SI ES META DE PRIMERA INFANCIA)
A63: META-062 | B63: 2024257770012 | C63: POR EL SUPATÁ SOÑADO AVANZAMOS JUNTOS EN LA LÍNEA ESTRATÉGICA SOCIAL | D63: POBLACIÓN VULNERABLE - CAPITULO PRIMERA INFANCIA, INFANCIA, ADOLESCENCIA Y JUVENTUD | E63: Realizar campañas anuales para la prevención de la conducta suicida, en niños, niñas, adolescentes y jovenes
A64: META-063 | B64: 2024257770012 | C64: POR EL SUPATÁ SOÑADO AVANZAMOS JUNTOS EN LA LÍNEA ESTRATÉGICA SOCIAL | D64: POBLACIÓN VULNERABLE - CAPITULO PRIMERA INFANCIA, INFANCIA, ADOLESCENCIA Y JUVENTUD | E64: Mantener a 100 niños de 0 a 5 años en establecimientos de educación inicial
A65: META-064 | B65: 2024257770012 | C65: POR EL SUPATÁ SOÑADO AVANZAMOS JUNTOS EN LA LÍNEA ESTRATÉGICA SOCIAL | D65: POBLACIÓN VULNERABLE - CAPITULO PRIMERA INFANCIA, INFANCIA, ADOLESCENCIA Y JUVENTUD | E65: Implementar un programa de apoyo integral a la juventud
A66: META-065 | B66: 2024257770013 | C66: POR EL SUPATÁ SOÑADO AVANZAMOS JUNTOS EN LA LÍNEA ESTRATÉGICA SOCIAL | D66: POBLACIÓN VULNERABLE- CAPITULO MUJER Y GENERO | E66: Construcción de (1) centro de innovación empresarial casa social de la mujer.
A67: META-066 | B67: 2024257770013 | C67: POR EL SUPATÁ SOÑADO AVANZAMOS JUNTOS EN LA LÍNEA ESTRATÉGICA SOCIAL | D67: POBLACIÓN VULNERABLE- CAPITULO MUJER Y GENERO | E67: Realizar anualmente mecanismos para la articulacion, actualización, reactivación y seguimiento de las actividades del Consejo Consultivo de Mujeres, como instancia de representación de sus necesidades e interés
A68: META-067 | B68: 2024257770014 | C68: POR EL SUPATÁ SOÑADO AVANZAMOS JUNTOS EN LA LÍNEA ESTRATÉGICA SOCIAL | D68: POBLACIÓN VULNERABLE - CAPITULO ADULTO MAYOR | E68: Mentener el Programa Centro Día Urbano y rural para el beneficio
A69: META-068 | B69: 2024257770014 | C69: POR EL SUPATÁ SOÑADO AVANZAMOS JUNTOS EN LA LÍNEA ESTRATÉGICA SOCIAL | D69: POBLACIÓN VULNERABLE - CAPITULO ADULTO MAYOR | E69: Garantizar la atención integral e institucional de adultos mayores con vulnerabilidad social en el centro de bienestar del adulto mayor "Maria Auxiliadora".
... A127: META-126 | B127: 2024257770021 | C127: POR EL SUPATÁ SOÑADO AVANZAMOS JUNTOS EN LA LÍNEA ESTRATÉGICA ECONÓMICA | D127: TRANSPORTE | E127: Realizar 300 metros lineales de señalizacion de vías terciarias y urbanas del municipio.
A128: META-127 | B128: 2024257770021 | E128: Realizar 4 capacitaciones sobre seguridad vial a los actores viales del municipio
A129: META-128 | B129: 2024257770023 | C129: POR EL SUPATÁ SOÑADO AVANZAMOS JUNTOS EN LA LÍNEA ESTRATÉGICA ECONÓMICA | D129: AGROPECUARIO | E129: Apoyo (2) proyectos productivos que me garanticen el uso eficiente en ganaderia y uso del suelo.
A130: META-129 | B130: 2024257770023 | C130: POR EL SUPATÁ SOÑADO AVANZAMOS JUNTOS EN LA LÍNEA ESTRATÉGICA ECONÓMICA | D130: AGROPECUARIO | E130: Realizar 400 visitas técnicas solicitada a los sistemas de producción agricolas
A131: META-130 | B131: 2024257770023 | C131: POR EL SUPATÁ SOÑADO AVANZAMOS JUNTOS EN LA LÍNEA ESTRATÉGICA ECONÓMICA | D131: AGROPECUARIO | E131: Implementar 80 huertas y huertos caseras
A132: META-131 | B132: 2024257770023 | C132: POR EL SUPATÁ SOÑADO AVANZAMOS JUNTOS EN LA LÍNEA ESTRATÉGICA ECONÓMICA | D132: AGROPECUARIO | E132: Apoyo a 20 pequeños productores cafeteros del municipio para aumentar las áreas de siembra, mejorar la capacidad productiva y competitividad, en el cuatrenio
A133: META-132 | B133: 2024257770023 | C133: POR EL SUPATÁ SOÑADO AVANZAMOS JUNTOS EN LA LÍNEA ESTRATÉGICA ECONÓMICA | D133: AGROPECUARIO | E133: Fortalecer el Programa de Mercados Campesinos para aumentar la comercializacion de los productos agropecuarios
A134: META-133 | B134: 2024257770023 | C134: POR EL SUPATÁ SOÑADO AVANZAMOS JUNTOS EN LA LÍNEA ESTRATÉGICA ECONÓMICA | D134: AGROPECUARIO | E134: Apoyar a 20 usuarios en la implementacion de sistemas de producción pecuaria con especies menores.
A135: META-134 | B135: 2024257770023 | C135: POR EL SUPATÁ SOÑADO AVANZAMOS JUNTOS EN LA LÍNEA ESTRATÉGICA ECONÓMICA | D135: AGROPECUARIO | E135: Fortalecer anualmente las asociasiones de productores legalmente constituidas
A136: META-135 | B136: 2024257770024 | C136: POR EL SUPATÁ SOÑADO AVANZAMOS JUNTOS EN LA LÍNEA ESTRATÉGICA ECONÓMICA | D136: AGROPECUARIO | E136: Capacitar a 100 personas que elaboren en fincas ganaderas en normatividad ICA
A137: META-136 | B137: 202500000009592 | C137: POR EL SUPATÁ SOÑADO AVANZAMOS JUNTOS EN LA LÍNEA ESTRATÉGICA ECONÓMICA | D137: AGROPECUARIO | E137: Organizar (4) ferias agropecuarias
A138: META-137 | B138: 202500000008911 | C138: POR EL SUPATÁ SOÑADO AVANZAMOS JUNTOS EN LA LÍNEA ESTRATÉGICA ECONÓMICA | D138: AGROPECUARIO | E138: Realizar 500 procedimientos de esterilización canina y felina con el fin de hacer control de población canina y felina
A139: META-138 | B139: 202500000009564 | C139: POR EL SUPATÁ SOÑADO AVANZAMOS JUNTOS EN LA LÍNEA ESTRATÉGICA ECONÓMICA | D139: AGROPECUARIO | E139: Crear el plan agropecuario municipal
...

Sheet SECRETARIAS
A1: COD_SECRETARIA | B1: SECRETARIA
A2: SG | B2: Secretaría General y de Gobierno
A3: SP | B3: Secretaría de Planeación y Obras Públicas
A4: SD | B4: Secretaría de Desarrollo Social y Comunitario
A5: SR | B5: Secretaría de Desarrollo Rural, Medio Ambiente y Competitividad
A6: SH | B6: Secretaría de Hacienda

Sheet LISTAS
A1: AÑOS | B1: ESTADOS | C1: FUENTE_FINANCIACION | D1: TIPO_EVIDENCIA
A2: 2024 | B2: No iniciada | C2: Recursos Propios | D2: Contrato
A3: 2025 | B3: En ejecución | C3: SGP | D3: Acta
B4: Cumplida | C4: Regalías | D4: Informe
C5: ICCU | D5: Foto
C6: CAR | D6: Certificado
C7: Gobernación | D7: Registro/Soporte
C8: Nación/Ministerios | D8: Otro
C9: Cooperación
C10: Mixta

Sheet REGISTRO_AVANCES
A1: AÑO | B1: SECRETARIA | C1: ID_META | D1: BPIM | E1: EJE | F1: SECTOR | G1: META_PRODUCTO | H1: META_PROGRAMADA_AÑO | I1: AVANCE_EJECUTADO_AÑO | J1: %_AVANCE_FISICO | K1: PRESUPUESTO_ASIGNADO | L1: PRESUPUESTO_EJECUTADO | M1: %_EJEC_FINANCIERA | N1: PROYECTO_ASOCIADO | O1: FUENTE_FINANCIACION | P1: ESTADO | Q1: TIPO_EVIDENCIA | R1: EVIDENCIA_ARCHIVO_O_RUTA | S1: OBSERVACIONES | T1: FECHA_REGISTRO | U1: RESPONSABLE
A2: 2024 | B2: Secretaría de Planeación y Obras Públicas | C2: META-117 | D2: =IF($C2="","",INDEX(PLAN_DESARROLLO!$B:$B,MATCH($C2,PLAN_DESARROLLO!$A:$A,0))) -> 2024257770021 | E2: =IF($C2="","",INDEX(PLAN_DESARROLLO!$C:$C,MATCH($C2,PLAN_DESARROLLO!$A:$A,0))) -> POR EL SUPATÁ SOÑADO AVANZAMOS JUNTOS EN LA LÍNEA ESTRATÉGICA ECONÓMICA | F2: =IF($C2="","",INDEX(PLAN_DESARROLLO!$D:$D,MATCH($C2,PLAN_DESARROLLO!$A:$A,0))) -> TRANSPORTE | G2: =IF($C2="","",INDEX(PLAN_DESARROLLO!$E:$E,MATCH($C2,PLAN_DESARROLLO!$A:$A,0))) -> Realizar mantenimiento rutinario de 50 Km de vías rurales del municipio (cuneteando, conformando, afirmado y compactado, según la necesidad) en el cuatrienio | H2: 50 | I2: 120 | J2: =IF(OR($H2="",$I2=""),"",IFERROR($I2/$H2,0)) -> 2.4 | K2: 600000000 | L2: 600000000 | M2: =IF(OR($K2="",$L2=""),"",IFERROR($L2/$K2,0)) -> 1 | N2: contrato de combustible, mantenimiento de la maquinaria, pago de los operarios, e incentivo a las juntas de accion comunal por medio de convenios solidarios | O2: Recursos Propios | P2: Cumplida | Q2: Informe | T2: =IF($A2="","",TODAY()) -> 46059
A3: 2025 | B3: Secretaría de Planeación y Obras Públicas | C3: META-117 | D3: =IF($C3="","",INDEX(PLAN_DESARROLLO!$B:$B,MATCH($C3,PLAN_DESARROLLO!$A:$A,0))) -> 2024257770021 | E3: =IF($C3="","",INDEX(PLAN_DESARROLLO!$C:$C,MATCH($C3,PLAN_DESARROLLO!$A:$A,0))) -> POR EL SUPATÁ SOÑADO AVANZAMOS JUNTOS EN LA LÍNEA ESTRATÉGICA ECONÓMICA | F3: =IF($C3="","",INDEX(PLAN_DESARROLLO!$D:$D,MATCH($C3,PLAN_DESARROLLO!$A:$A,0))) -> TRANSPORTE | G3: =IF($C3="","",INDEX(PLAN_DESARROLLO!$E:$E,MATCH($C3,PLAN_DESARROLLO!$A:$A,0))) -> Realizar mantenimiento rutinario de 50 Km de vías rurales del municipio (cuneteando, conformando, afirmado y compactado, según la necesidad) en el cuatrienio | H3: 50 | I3: 300 | J3: =IF(OR($H3="",$I3=""),"",IFERROR($I3/$H3,0)) -> 6 | K3: 600000000 | L3: 1500000000 | M3: =IF(OR($K3="",$L3=""),"",IFERROR($L3/$K3,0)) -> 2.5 | N3: contrato de combustible, mantenimiento de la maquinaria, pago de los operarios, e incentivo a las juntas de accion comunal por medio de convenios solidarios | O3: Recursos Propios | P3: Cumplida | Q3: Informe | T3: =IF($A3="","",TODAY()) -> 46059
A4: 2024 | B4: Secretaría de Planeación y Obras Públicas | C4: META-118 | D4: =IF($C4="","",INDEX(PLAN_DESARROLLO!$B:$B,MATCH($C4,PLAN_DESARROLLO!$A:$A,0))) -> 2024257770021 | E4: =IF($C4="","",INDEX(PLAN_DESARROLLO!$C:$C,MATCH($C4,PLAN_DESARROLLO!$A:$A,0))) -> POR EL SUPATÁ SOÑADO AVANZAMOS JUNTOS EN LA LÍNEA ESTRATÉGICA ECONÓMICA | F4: =IF($C4="","",INDEX(PLAN_DESARROLLO!$D:$D,MATCH($C4,PLAN_DESARROLLO!$A:$A,0))) -> TRANSPORTE | G4: =IF($C4="","",INDEX(PLAN_DESARROLLO!$E:$E,MATCH($C4,PLAN_DESARROLLO!$A:$A,0))) -> Realizar el mejoramiento, adecuación de vías en la zona rural a través de la construcción de 1.000 ML de placa huellas en concreto o pavimentación, en el cuatrienio | H4: 1000 | I4: 400 | J4: =IF(OR($H4="",$I4=""),"",IFERROR($I4/$H4,0)) -> 0.4 | K4: 600000000 | L4: 300000000 | M4: =IF(OR($K4="",$L4=""),"",IFERROR($L4/$K4,0)) -> 0.5 | N4: convenios solidarios con las juntas de accion comunal | O4: Cooperación | P4: En ejecución | Q4: Otro | T4: =IF($A4="","",TODAY()) -> 46059
A5: 2025 | B5: Secretaría de Planeación y Obras Públicas | C5: META-118 | D5: =IF($C5="","",INDEX(PLAN_DESARROLLO!$B:$B,MATCH($C5,PLAN_DESARROLLO!$A:$A,0))) -> 2024257770021 | E5: =IF($C5="","",INDEX(PLAN_DESARROLLO!$C:$C,MATCH($C5,PLAN_DESARROLLO!$A:$A,0))) -> POR EL SUPATÁ SOÑADO AVANZAMOS JUNTOS EN LA LÍNEA ESTRATÉGICA ECONÓMICA | F5: =IF($C5="","",INDEX(PLAN_DESARROLLO!$D:$D,MATCH($C5,PLAN_DESARROLLO!$A:$A,0))) -> TRANSPORTE | G5: =IF($C5="","",INDEX(PLAN_DESARROLLO!$E:$E,MATCH($C5,PLAN_DESARROLLO!$A:$A,0))) -> Realizar el mejoramiento, adecuación de vías en la zona rural a través de la construcción de 1.000 ML de placa huellas en concreto o pavimentación, en el cuatrienio | H5: 1000 | I5: 2000 | J5: =IF(OR($H5="",$I5=""),"",IFERROR($I5/$H5,0)) -> 2 | K5: 600000000 | L5: 2000000000 | M5: =IF(OR($K5="",$L5=""),"",IFERROR($L5/$K5,0)) -> 3.3333333 | N5: convenios interadministrativos, con la gobernacion de cundinamarca | O5: Gobernación | P5: Cumplida | Q5: Informe | T5: =IF($A5="","",TODAY()) -> 46059
A6: 2024 | B6: Secretaría de Planeación y Obras Públicas | C6: META-119 | D6: =IF($C6="","",INDEX(PLAN_DESARROLLO!$B:$B,MATCH($C6,PLAN_DESARROLLO!$A:$A,0))) -> 2024257770021 | E6: =IF($C6="","",INDEX(PLAN_DESARROLLO!$C:$C,MATCH($C6,PLAN_DESARROLLO!$A:$A,0))) -> POR EL SUPATÁ SOÑADO AVANZAMOS JUNTOS EN LA LÍNEA ESTRATÉGICA ECONÓMICA | F6: =IF($C6="","",INDEX(PLAN_DESARROLLO!$D:$D,MATCH($C6,PLAN_DESARROLLO!$A:$A,0))) -> TRANSPORTE | G6: =IF($C6="","",INDEX(PLAN_DESARROLLO!$E:$E,MATCH($C6,PLAN_DESARROLLO!$A:$A,0))) -> Construir 10 obras de arte para el mantenimiento y mejoramiento de la red terciaria del municipio, durante el cuatrienio | H6: 5 | I6: 2 | J6: =IF(OR($H6="",$I6=""),"",IFERROR($I6/$H6,0)) -> 0.4 | K6: 150000000 | L6: 150000000 | M6: =IF(OR($K6="",$L6=""),"",IFERROR($L6/$K6,0)) -> 1 | N6: arreglos y mantenimiento a la alcantarillas y arreglo de pasos rurales en conjunto con las juntas de accion comunal | O6: SGP | P6: En ejecución | Q6: Informe
A7: 2025 | B7: Secretaría de Planeación y Obras Públicas | C7: META-119 | D7: =IF($C7="","",INDEX(PLAN_DESARROLLO!$B:$B,MATCH($C7,PLAN_DESARROLLO!$A:$A,0))) -> 2024257770021 | E7: =IF($C7="","",INDEX(PLAN_DESARROLLO!$C:$C,MATCH($C7,PLAN_DESARROLLO!$A:$A,0))) -> POR EL SUPATÁ SOÑADO AVANZAMOS JUNTOS EN LA LÍNEA ESTRATÉGICA ECONÓMICA | F7: =IF($C7="","",INDEX(PLAN_DESARROLLO!$D:$D,MATCH($C7,PLAN_DESARROLLO!$A:$A,0))) -> TRANSPORTE | G7: =IF($C7="","",INDEX(PLAN_DESARROLLO!$E:$E,MATCH($C7,PLAN_DESARROLLO!$A:$A,0))) -> Construir 10 obras de arte para el mantenimiento y mejoramiento de la red terciaria del municipio, durante el cuatrienio | H7: 5 | I7: 5 | J7: =IF(OR($H7="",$I7=""),"",IFERROR($I7/$H7,0)) -> 1 | K7: 300000000 | L7: 300000000 | M7: =IF(OR($K7="",$L7=""),"",IFERROR($L7/$K7,0)) -> 1 | N7: arreglos y mantenimiento a la alcantarillas y arreglo de pasos rurales en conjunto con las juntas de accion comunal | O7: SGP | P7: Cumplida | Q7: Informe | T7: =IF($A7="","",TODAY()) -> 46059
A8: 2024 | B8: Secretaría de Planeación y Obras Públicas | C8: META-046 | D8: =IF($C8="","",INDEX(PLAN_DESARROLLO!$B:$B,MATCH($C8,PLAN_DESARROLLO!$A:$A,0))) -> 2024257770010 | E8: =IF($C8="","",INDEX(PLAN_DESARROLLO!$C:$C,MATCH($C8,PLAN_DESARROLLO!$A:$A,0))) -> POR EL SUPATÁ SOÑADO AVANZAMOS JUNTOS EN LA LÍNEA ESTRATÉGICA SOCIAL | F8: =IF($C8="","",INDEX(PLAN_DESARROLLO!$D:$D,MATCH($C8,PLAN_DESARROLLO!$A:$A,0))) -> RECREACION Y DEPROTE | G8: =IF($C8="","",INDEX(PLAN_DESARROLLO!$E:$E,MATCH($C8,PLAN_DESARROLLO!$A:$A,0))) -> Realizar 2 estudios y diseños para infraestructura deportiva y recreativa en el municipio | H8: 2 | I8: 0 | J8: =IF(OR($H8="",$I8=""),"",IFERROR($I8/$H8,0)) -> 0 | K8: 0 | L8: 0 | M8: =IF(OR($K8="",$L8=""),"",IFERROR($L8/$K8,0)) -> 0 | N8: en proceso de estudios y diseños | O8: Recursos Propios | P8: No iniciada | Q8: Otro | T8: =IF($A8="","",TODAY()) -> 46059
A9: 2025 | B9: Secretaría de Planeación y Obras Públicas | C9: META-046 | D9: =IF($C9="","",INDEX(PLAN_DESARROLLO!$B:$B,MATCH($C9,PLAN_DESARROLLO!$A:$A,0))) -> 2024257770010 | E9: =IF($C9="","",INDEX(PLAN_DESARROLLO!$C:$C,MATCH($C9,PLAN_DESARROLLO!$A:$A,0))) -> POR EL SUPATÁ SOÑADO AVANZAMOS JUNTOS EN LA LÍNEA ESTRATÉGICA SOCIAL | F9: =IF($C9="","",INDEX(PLAN_DESARROLLO!$D:$D,MATCH($C9,PLAN_DESARROLLO!$A:$A,0))) -> RECREACION Y DEPROTE | G9: =IF($C9="","",INDEX(PLAN_DESARROLLO!$E:$E,MATCH($C9,PLAN_DESARROLLO!$A:$A,0))) -> Realizar 2 estudios y diseños para infraestructura deportiva y recreativa en el municipio | H9: 2 | I9: 2 | J9: =IF(OR($H9="",$I9=""),"",IFERROR($I9/$H9,0)) -> 1 | K9: 0 | L9: 0 | M9: =IF(OR($K9="",$L9=""),"",IFERROR($L9/$K9,0)) -> 0 | N9: estudios y diseños realizados | O9: Recursos Propios | P9: En ejecución | Q9: Informe | T9: =IF($A9="","",TODAY()) -> 46059
A10: 2024 | B10: Secretaría de Planeación y Obras Públicas | C10: META-079 | D10: =IF($C10="","",INDEX(PLAN_DESARROLLO!$B:$B,MATCH($C10,PLAN_DESARROLLO!$A:$A,0))) -> 2024257770016 | E10: =IF($C10="","",INDEX(PLAN_DESARROLLO!$C:$C,MATCH($C10,PLAN_DESARROLLO!$A:$A,0))) -> POR EL SUPATÁ SOÑADO AVANZAMOS JUNTOS EN LA LÍNEA ESTRATÉGICA SOCIAL | F10: =IF($C10="","",INDEX(PLAN_DESARROLLO!$D:$D,MATCH($C10,PLAN_DESARROLLO!$A:$A,0))) -> VIVIENDA, CIUDAD Y TERRITORIO | G10: =IF($C10="","",INDEX(PLAN_DESARROLLO!$E:$E,MATCH($C10,PLAN_DESARROLLO!$A:$A,0))) -> Fortalecer administrativa y logística anualmente el Consejo Territorial de Planeación para su funcionamiento. (pendiente fortalecimiento institucional cambio de sector) | H10: 1 | I10: 1 | J10: =IF(OR($H10="",$I10=""),"",IFERROR($I10/$H10,0)) -> 1 | K10: 0 | L10: 0 | M10: =IF(OR($K10="",$L10=""),"",IFERROR($L10/$K10,0)) -> 0 | N10: se envia a los miembros del comité informacion sobre capacitaciones | O10: Cooperación | P10: En ejecución | Q10: Otro | T10: =IF($A10="","",TODAY()) -> 46059
A11: 2025 | B11: Secretaría de Planeación y Obras Públicas | C11: META-079 | D11: =IF($C11="","",INDEX(PLAN_DESARROLLO!$B:$B,MATCH($C11,PLAN_DESARROLLO!$A:$A,0))) -> 2024257770016 | E11: =IF($C11="","",INDEX(PLAN_DESARROLLO!$C:$C,MATCH($C11,PLAN_DESARROLLO!$A:$A,0))) -> POR EL SUPATÁ SOÑADO AVANZAMOS JUNTOS EN LA LÍNEA ESTRATÉGICA SOCIAL | F11: =IF($C11="","",INDEX(PLAN_DESARROLLO!$D:$D,MATCH($C11,PLAN_DESARROLLO!$A:$A,0))) -> VIVIENDA, CIUDAD Y TERRITORIO | G11: =IF($C11="","",INDEX(PLAN_DESARROLLO!$E:$E,MATCH($C11,PLAN_DESARROLLO!$A:$A,0))) -> Fortalecer administrativa y logística anualmente el Consejo Territorial de Planeación para su funcionamiento. (pendiente fortalecimiento institucional cambio de sector) | H11: 1 | I11: 1 | J11: =IF(OR($H11="",$I11=""),"",IFERROR($I11/$H11,0)) -> 1 | K11: 0 | L11: 0 | M11: =IF(OR($K11="",$L11=""),"",IFERROR($L11/$K11,0)) -> 0 | N11: se envia a los miembros del comité informacion sobre capacitaciones | O11: Cooperación | P11: En ejecución | Q11: Otro | T11: =IF($A11="","",TODAY()) -> 46059
A12: 2024 | B12: Secretaría de Planeación y Obras Públicas | C12: META-080 | D12: =IF($C12="","",INDEX(PLAN_DESARROLLO!$B:$B,MATCH($C12,PLAN_DESARROLLO!$A:$A,0))) -> 2024257770016 | E12: =IF($C12="","",INDEX(PLAN_DESARROLLO!$C:$C,MATCH($C12,PLAN_DESARROLLO!$A:$A,0))) -> POR EL SUPATÁ SOÑADO AVANZAMOS JUNTOS EN LA LÍNEA ESTRATÉGICA SOCIAL | F12: =IF($C12="","",INDEX(PLAN_DESARROLLO!$D:$D,MATCH($C12,PLAN_DESARROLLO!$A:$A,0))) -> VIVIENDA, CIUDAD Y TERRITORIO | G12: =IF($C12="","",INDEX(PLAN_DESARROLLO!$E:$E,MATCH($C12,PLAN_DESARROLLO!$A:$A,0))) -> Adecuación y mantenimiento de la plaza de ferias municipal | H12: 1 | I12: 0 | J12: =IF(OR($H12="",$I12=""),"",IFERROR($I12/$H12,0)) -> 0 | K12: 0 | L12: 0 | M12: =IF(OR($K12="",$L12=""),"",IFERROR($L12/$K12,0)) -> 0 | N12: en proceso de estudios y diseños | O12: Regalías | P12: No iniciada | Q12: Otro | T12: =IF($A12="","",TODAY()) -> 46059
A13: 2025 | B13: Secretaría de Planeación y Obras Públicas | C13: META-080 | D13: =IF($C13="","",INDEX(PLAN_DESARROLLO!$B:$B,MATCH($C13,PLAN_DESARROLLO!$A:$A,0))) -> 2024257770016 | E13: =IF($C13="","",INDEX(PLAN_DESARROLLO!$C:$C,MATCH($C13,PLAN_DESARROLLO!$A:$A,0))) -> POR EL SUPATÁ SOÑADO AVANZAMOS JUNTOS EN LA LÍNEA ESTRATÉGICA SOCIAL | F13: =IF($C13="","",INDEX(PLAN_DESARROLLO!$D:$D,MATCH($C13,PLAN_DESARROLLO!$A:$A,0))) -> VIVIENDA, CIUDAD Y TERRITORIO | G13: =IF($C13="","",INDEX(PLAN_DESARROLLO!$E:$E,MATCH($C13,PLAN_DESARROLLO!$A:$A,0))) -> Adecuación y mantenimiento de la plaza de ferias municipal | H13: 1 | I13: 1 | J13: =IF(OR($H13="",$I13=""),"",IFERROR($I13/$H13,0)) -> 1 | K13: 1700000000 | L13: 1700000000 | M13: =IF(OR($K13="",$L13=""),"",IFERROR($L13/$K13,0)) -> 1 | N13: estudios y diseños avalados por regalias y en proceso de cadjudicación | O13: Regalías | P13: En ejecución | Q13: Informe | T13: =IF($A13="","",TODAY()) -> 46059
A14: 2024 | B14: Secretaría de Planeación y Obras Públicas | C14: META-081 | D14: =IF($C14="","",INDEX(PLAN_DESARROLLO!$B:$B,MATCH($C14,PLAN_DESARROLLO!$A:$A,0))) -> 2024257770016 | E14: =IF($C14="","",INDEX(PLAN_DESARROLLO!$C:$C,MATCH($C14,PLAN_DESARROLLO!$A:$A,0))) -> POR EL SUPATÁ SOÑADO AVANZAMOS JUNTOS EN LA LÍNEA ESTRATÉGICA SOCIAL | F14: =IF($C14="","",INDEX(PLAN_DESARROLLO!$D:$D,MATCH($C14,PLAN_DESARROLLO!$A:$A,0))) -> VIVIENDA, CIUDAD Y TERRITORIO | G14: =IF($C14="","",INDEX(PLAN_DESARROLLO!$E:$E,MATCH($C14,PLAN_DESARROLLO!$A:$A,0))) -> Realizar 2 mantenimientos a la plaza de mercado | H14: 2 | I14: 0 | J14: =IF(OR($H14="",$I14=""),"",IFERROR($I14/$H14,0)) -> 0 | K14: 0 | L14: 0 | M14: =IF(OR($K14="",$L14=""),"",IFERROR($L14/$K14,0)) -> 0 | N14: en proceso de estudios | O14: Recursos Propios | P14: No iniciada | Q14: Informe | T14: =IF($A14="","",TODAY()) -> 46059
A15: 2025 | B15: Secretaría de Planeación y Obras Públicas | C15: META-081 | D15: =IF($C15="","",INDEX(PLAN_DESARROLLO!$B:$B,MATCH($C15,PLAN_DESARROLLO!$A:$A,0))) -> 2024257770016 | E15: =IF($C15="","",INDEX(PLAN_DESARROLLO!$C:$C,MATCH($C15,PLAN_DESARROLLO!$A:$A,0))) -> POR EL SUPATÁ SOÑADO AVANZAMOS JUNTOS EN LA LÍNEA ESTRATÉGICA SOCIAL | F15: =IF($C15="","",INDEX(PLAN_DESARROLLO!$D:$D,MATCH($C15,PLAN_DESARROLLO!$A:$A,0))) -> VIVIENDA, CIUDAD Y TERRITORIO | G15: =IF($C15="","",INDEX(PLAN_DESARROLLO!$E:$E,MATCH($C15,PLAN_DESARROLLO!$A:$A,0))) -> Realizar 2 mantenimientos a la plaza de mercado | H15: 2 | I15: 0 | J15: =IF(OR($H15="",$I15=""),"",IFERROR($I15/$H15,0)) -> 0 | K15: 0 | L15: 0 | M15: =IF(OR($K15="",$L15=""),"",IFERROR($L15/$K15,0)) -> 0 | N15: en proceso de estudios | O15: Recursos Propios | P15: No iniciada | Q15: Informe | T15: =IF($A15="","",TODAY()) -> 46059
A16: 2024 | B16: Secretaría de Planeación y Obras Públicas | C16: META-082 | D16: =IF($C16="","",INDEX(PLAN_DESARROLLO!$B:$B,MATCH($C16,PLAN_DESARROLLO!$A:$A,0))) -> 2024257770016 | E16: =IF($C16="","",INDEX(PLAN_DESARROLLO!$C:$C,MATCH($C16,PLAN_DESARROLLO!$A:$A,0))) -> POR EL SUPATÁ SOÑADO AVANZAMOS JUNTOS EN LA LÍNEA ESTRATÉGICA SOCIAL | F16: =IF($C16="","",INDEX(PLAN_DESARROLLO!$D:$D,MATCH($C16,PLAN_DESARROLLO!$A:$A,0))) -> VIVIENDA, CIUDAD Y TERRITORIO | G16: =IF($C16="","",INDEX(PLAN_DESARROLLO!$E:$E,MATCH($C16,PLAN_DESARROLLO!$A:$A,0))) -> Implementar el programa anual de Banco de Materiales que une esfuerzos entre la administración municipal y la comunidad para la realización de obras necesarias y de gran impacto social en barrios y veredas. | H16: 1 | I16: 1 | J16: =IF(OR($H16="",$I16=""),"",IFERROR($I16/$H16,0)) -> 1 | K16: 30000000 | L16: 30000000 | M16: =IF(OR($K16="",$L16=""),"",IFERROR($L16/$K16,0)) -> 1 | N16: se contrato el proceso de banco de materiales | O16: Recursos Propios | P16: Cumplida | Q16: Informe | T16: =IF($A16="","",TODAY()) -> 46059
A17: 2025 | B17: Secretaría de Planeación y Obras Públicas | C17: META-082 | D17: =IF($C17="","",INDEX(PLAN_DESARROLLO!$B:$B,MATCH($C17,PLAN_DESARROLLO!$A:$A,0))) -> 2024257770016 | E17: =IF($C17="","",INDEX(PLAN_DESARROLLO!$C:$C,MATCH($C17,PLAN_DESARROLLO!$A:$A,0))) -> POR EL SUPATÁ SOÑADO AVANZAMOS JUNTOS EN LA LÍNEA ESTRATÉGICA SOCIAL | F17: =IF($C17="","",INDEX(PLAN_DESARROLLO!$D:$D,MATCH($C17,PLAN_DESARROLLO!$A:$A,0))) -> VIVIENDA, CIUDAD Y TERRITORIO | G17: =IF($C17="","",INDEX(PLAN_DESARROLLO!$E:$E,MATCH($C17,PLAN_DESARROLLO!$A:$A,0))) -> Implementar el programa anual de Banco de Materiales que une esfuerzos entre la administración municipal y la comunidad para la realización de obras necesarias y de gran impacto social en barrios y veredas. | H17: 1 | I17: 1 | J17: =IF(OR($H17="",$I17=""),"",IFERROR($I17/$H17,0)) -> 1 | K17: 46000000 | L17: 46000000 | M17: =IF(OR($K17="",$L17=""),"",IFERROR($L17/$K17,0)) -> 1 | N17: se contrato el proceso de banco de materiales y elementos de ferreteria | O17: Recursos Propios | P17: Cumplida | Q17: Informe | T17: =IF($A17="","",TODAY()) -> 46059
A18: 2024 | B18: Secretaría de Planeación y Obras Públicas | C18: META-083 | D18: =IF($C18="","",INDEX(PLAN_DESARROLLO!$B:$B,MATCH($C18,PLAN_DESARROLLO!$A:$A,0))) -> 2024257770016 | E18: =IF($C18="","",INDEX(PLAN_DESARROLLO!$C:$C,MATCH($C18,PLAN_DESARROLLO!$A:$A,0))) -> POR EL SUPATÁ SOÑADO AVANZAMOS JUNTOS EN LA LÍNEA ESTRATÉGICA SOCIAL | F18: =IF($C18="","",INDEX(PLAN_DESARROLLO!$D:$D,MATCH($C18,PLAN_DESARROLLO!$A:$A,0))) -> VIVIENDA, CIUDAD Y TERRITORIO | G18: =IF($C18="","",INDEX(PLAN_DESARROLLO!$E:$E,MATCH($C18,PLAN_DESARROLLO!$A:$A,0))) -> Implementar un programa de mantenimiento de espacio público, zonas verdes y parques del municipio | H18: 1 | I18: 1 | J18: =IF(OR($H18="",$I18=""),"",IFERROR($I18/$H18,0)) -> 1 | K18: 50000000 | L18: 50000000 | M18: =IF(OR($K18="",$L18=""),"",IFERROR($L18/$K18,0)) -> 1 | N18: se realizan mantenimientos, pero tambien la contratacion del personal para el cuidado y preservacion de estos espacios | O18: SGP | P18: Cumplida | Q18: Informe | T18: =IF($A18="","",TODAY()) -> 46059
... A23: 2025 | B23: Secretaría de Planeación y Obras Públicas | C23: META-085 | D23: =IF($C23="","",INDEX(PLAN_DESARROLLO!$B:$B,MATCH($C23,PLAN_DESARROLLO!$A:$A,0))) -> 2024257770016 | E23: =IF($C23="","",INDEX(PLAN_DESARROLLO!$C:$C,MATCH($C23,PLAN_DESARROLLO!$A:$A,0))) -> POR EL SUPATÁ SOÑADO AVANZAMOS JUNTOS EN LA LÍNEA ESTRATÉGICA SOCIAL | F23: =IF($C23="","",INDEX(PLAN_DESARROLLO!$D:$D,MATCH($C23,PLAN_DESARROLLO!$A:$A,0))) -> VIVIENDA, CIUDAD Y TERRITORIO | G23: =IF($C23="","",INDEX(PLAN_DESARROLLO!$E:$E,MATCH($C23,PLAN_DESARROLLO!$A:$A,0))) -> Estudios y diseños para la construcción de la casa de gobierno | H23: 1 | I23: 1 | J23: =IF(OR($H23="",$I23=""),"",IFERROR($I23/$H23,0)) -> 1 | K23: 0 | L23: 0 | M23: =IF(OR($K23="",$L23=""),"",IFERROR($L23/$K23,0)) -> 0 | N23: en proceso de adjudicacion luego de ser aprobados los estudios y diseños, en convenio entre la gobernacion de cundinamarca y los fondos por regalias | O23: Mixta | P23: Cumplida | Q23: Informe | T23: =IF($A23="","",TODAY()) -> 46059
A24: 2024 | B24: Secretaría de Planeación y Obras Públicas | C24: META-086 | D24: =IF($C24="","",INDEX(PLAN_DESARROLLO!$B:$B,MATCH($C24,PLAN_DESARROLLO!$A:$A,0))) -> 2024257770017 | E24: =IF($C24="","",INDEX(PLAN_DESARROLLO!$C:$C,MATCH($C24,PLAN_DESARROLLO!$A:$A,0))) -> POR EL SUPATÁ SOÑADO AVANZAMOS JUNTOS EN LA LÍNEA ESTRATÉGICA SOCIAL | F24: =IF($C24="","",INDEX(PLAN_DESARROLLO!$D:$D,MATCH($C24,PLAN_DESARROLLO!$A:$A,0))) -> A.P.S.B | G24: =IF($C24="","",INDEX(PLAN_DESARROLLO!$E:$E,MATCH($C24,PLAN_DESARROLLO!$A:$A,0))) -> Realizar 1 optimizacion a la planta de tratamiento de agua potable | H24: 0 | I24: 0 | J24: =IF(OR($H24="",$I24=""),"",IFERROR($I24/$H24,0)) -> 0 | K24: 0 | L24: 0 | M24: =IF(OR($K24="",$L24=""),"",IFERROR($L24/$K24,0)) -> 0 | T24: =IF($A24="","",TODAY()) -> 46059
A25: 2025 | B25: Secretaría de Planeación y Obras Públicas | C25: META-086 | D25: =IF($C25="","",INDEX(PLAN_DESARROLLO!$B:$B,MATCH($C25,PLAN_DESARROLLO!$A:$A,0))) -> 2024257770017 | E25: =IF($C25="","",INDEX(PLAN_DESARROLLO!$C:$C,MATCH($C25,PLAN_DESARROLLO!$A:$A,0))) -> POR EL SUPATÁ SOÑADO AVANZAMOS JUNTOS EN LA LÍNEA ESTRATÉGICA SOCIAL | F25: =IF($C25="","",INDEX(PLAN_DESARROLLO!$D:$D,MATCH($C25,PLAN_DESARROLLO!$A:$A,0))) -> A.P.S.B | G25: =IF($C25="","",INDEX(PLAN_DESARROLLO!$E:$E,MATCH($C25,PLAN_DESARROLLO!$A:$A,0))) -> Realizar 1 optimizacion a la planta de tratamiento de agua potable | H25: 1 | I25: 1 | J25: =IF(OR($H25="",$I25=""),"",IFERROR($I25/$H25,0)) -> 1 | K25: 57470328 | L25: 57470328 | M25: =IF(OR($K25="",$L25=""),"",IFERROR($L25/$K25,0)) -> 1 | N25: Contrato de Obra Pública No. 004-2025 Adecuación y mejoramiento de la planta de tratamiento de agua potable del Municipio de Supatá Cundinamarca | O25: SGP - APSB | P25: En ejecución | Q25: Informe | T25: =IF($A25="","",TODAY()) -> 46059
A26: 2024 | B26: Secretaría de Planeación y Obras Públicas | C26: META-087 | D26: =IF($C26="","",INDEX(PLAN_DESARROLLO!$B:$B,MATCH($C26,PLAN_DESARROLLO!$A:$A,0))) -> 2024257770017 | E26: =IF($C26="","",INDEX(PLAN_DESARROLLO!$C:$C,MATCH($C26,PLAN_DESARROLLO!$A:$A,0))) -> POR EL SUPATÁ SOÑADO AVANZAMOS JUNTOS EN LA LÍNEA ESTRATÉGICA SOCIAL | F26: =IF($C26="","",INDEX(PLAN_DESARROLLO!$D:$D,MATCH($C26,PLAN_DESARROLLO!$A:$A,0))) -> A.P.S.B | G26: =IF($C26="","",INDEX(PLAN_DESARROLLO!$E:$E,MATCH($C26,PLAN_DESARROLLO!$A:$A,0))) -> Otorgar anualmente subsidios a los usuarios de los servicios de acueducto, de los estratos 1, 2 y 3 del área urbana,en el cuatrienio | H26: 1 | I26: 1 | J26: =IF(OR($H26="",$I26=""),"",IFERROR($I26/$H26,0)) -> 1 | K26: 22731829 | L26: 22731829 | M26: =IF(OR($K26="",$L26=""),"",IFERROR($L26/$K26,0)) -> 1 | N26: Pago de subsidios del servicio de Acueducto | O26: SGP - APSB | P26: Cumplida | Q26: Certificación | T26: =IF($A26="","",TODAY()) -> 46059
A27: 2025 | B27: Secretaría de Planeación y Obras Públicas | C27: META-087 | D27: =IF($C27="","",INDEX(PLAN_DESARROLLO!$B:$B,MATCH($C27,PLAN_DESARROLLO!$A:$A,0))) -> 2024257770017 | E27: =IF($C27="","",INDEX(PLAN_DESARROLLO!$C:$C,MATCH($C27,PLAN_DESARROLLO!$A:$A,0))) -> POR EL SUPATÁ SOÑADO AVANZAMOS JUNTOS EN LA LÍNEA ESTRATÉGICA SOCIAL | F27: =IF($C27="","",INDEX(PLAN_DESARROLLO!$D:$D,MATCH($C27,PLAN_DESARROLLO!$A:$A,0))) -> A.P.S.B | G27: =IF($C27="","",INDEX(PLAN_DESARROLLO!$E:$E,MATCH($C27,PLAN_DESARROLLO!$A:$A,0))) -> Otorgar anualmente subsidios a los usuarios de los servicios de acueducto, de los estratos 1, 2 y 3 del área urbana,en el cuatrienio | H27: 1 | I27: 1 | J27: =IF(OR($H27="",$I27=""),"",IFERROR($I27/$H27,0)) -> 1 | K27: 25162536 | L27: 25162536 | M27: =IF(OR($K27="",$L27=""),"",IFERROR($L27/$K27,0)) -> 1 | N27: Pago de subsidios del servicio de Acueducto | O27: SGP - APSB | P27: Cumplida | Q27: Certificación | T27: =IF($A27="","",TODAY()) -> 46059
A28: 2024 | B28: Secretaría de Planeación y Obras Públicas | C28: META-088 | D28: =IF($C28="","",INDEX(PLAN_DESARROLLO!$B:$B,MATCH($C28,PLAN_DESARROLLO!$A:$A,0))) -> 2024257770017 | E28: =IF($C28="","",INDEX(PLAN_DESARROLLO!$C:$C,MATCH($C28,PLAN_DESARROLLO!$A:$A,0))) -> POR EL SUPATÁ SOÑADO AVANZAMOS JUNTOS EN LA LÍNEA ESTRATÉGICA SOCIAL | F28: =IF($C28="","",INDEX(PLAN_DESARROLLO!$D:$D,MATCH($C28,PLAN_DESARROLLO!$A:$A,0))) -> A.P.S.B | G28: =IF($C28="","",INDEX(PLAN_DESARROLLO!$E:$E,MATCH($C28,PLAN_DESARROLLO!$A:$A,0))) -> Realizar optimizaciones a los acueductos veredales | H28: 1 | I28: 0 | J28: =IF(OR($H28="",$I28=""),"",IFERROR($I28/$H28,0)) -> 0 | K28: 0 | L28: 0 | M28: =IF(OR($K28="",$L28=""),"",IFERROR($L28/$K28,0)) -> 0 | T28: =IF($A28="","",TODAY()) -> 46059
A29: 2025 | B29: Secretaría de Planeación y Obras Públicas | C29: META-088 | D29: =IF($C29="","",INDEX(PLAN_DESARROLLO!$B:$B,MATCH($C29,PLAN_DESARROLLO!$A:$A,0))) -> 2024257770017 | E29: =IF($C29="","",INDEX(PLAN_DESARROLLO!$C:$C,MATCH($C29,PLAN_DESARROLLO!$A:$A,0))) -> POR EL SUPATÁ SOÑADO AVANZAMOS JUNTOS EN LA LÍNEA ESTRATÉGICA SOCIAL | F29: =IF($C29="","",INDEX(PLAN_DESARROLLO!$D:$D,MATCH($C29,PLAN_DESARROLLO!$A:$A,0))) -> A.P.S.B | G29: =IF($C29="","",INDEX(PLAN_DESARROLLO!$E:$E,MATCH($C29,PLAN_DESARROLLO!$A:$A,0))) -> Realizar optimizaciones a los acueductos veredales | H29: 1 | I29: 2 | J29: =IF(OR($H29="",$I29=""),"",IFERROR($I29/$H29,0)) -> 2 | K29: =98381800+127531800 -> 225913600 | L29: =98381800+127531800 -> 225913600 | M29: =IF(OR($K29="",$L29=""),"",IFERROR($L29/$K29,0)) -> 1 | N29: Convenio de Asociacion No EPC-PDA-CAS-024 y EPC-PDA-CAS-021 entre Empresas Publicas de Cundinamarca - EPC y las asociaciones de acueudcto de Cabrera y el Acueducto Regional de las veredas Santa Rosa, Providencia, Cristales y Mesitas, para el fortalecimiento institucional, comercial, técnico y financiero. | O29: SGP - APSB PDA | P29: Cumplida | Q29: Informe | T29: =IF($A29="","",TODAY()) -> 46059
A30: 2024 | B30: Secretaría de Planeación y Obras Públicas | C30: META-089 | D30: =IF($C30="","",INDEX(PLAN_DESARROLLO!$B:$B,MATCH($C30,PLAN_DESARROLLO!$A:$A,0))) -> 2024257770017 | E30: =IF($C30="","",INDEX(PLAN_DESARROLLO!$C:$C,MATCH($C30,PLAN_DESARROLLO!$A:$A,0))) -> POR EL SUPATÁ SOÑADO AVANZAMOS JUNTOS EN LA LÍNEA ESTRATÉGICA SOCIAL | F30: =IF($C30="","",INDEX(PLAN_DESARROLLO!$D:$D,MATCH($C30,PLAN_DESARROLLO!$A:$A,0))) -> A.P.S.B | G30: =IF($C30="","",INDEX(PLAN_DESARROLLO!$E:$E,MATCH($C30,PLAN_DESARROLLO!$A:$A,0))) -> Realizar la construcción de 200 metros lineales de red de acueducto en el municipio | H30: 0 | I30: 0 | J30: =IF(OR($H30="",$I30=""),"",IFERROR($I30/$H30,0)) -> 0 | K30: 0 | L30: 0 | M30: =IF(OR($K30="",$L30=""),"",IFERROR($L30/$K30,0)) -> 0 | T30: =IF($A30="","",TODAY()) -> 46059
A31: 2025 | B31: Secretaría de Planeación y Obras Públicas | C31: META-089 | D31: =IF($C31="","",INDEX(PLAN_DESARROLLO!$B:$B,MATCH($C31,PLAN_DESARROLLO!$A:$A,0))) -> 2024257770017 | E31: =IF($C31="","",INDEX(PLAN_DESARROLLO!$C:$C,MATCH($C31,PLAN_DESARROLLO!$A:$A,0))) -> POR EL SUPATÁ SOÑADO AVANZAMOS JUNTOS EN LA LÍNEA ESTRATÉGICA SOCIAL | F31: =IF($C31="","",INDEX(PLAN_DESARROLLO!$D:$D,MATCH($C31,PLAN_DESARROLLO!$A:$A,0))) -> A.P.S.B | G31: =IF($C31="","",INDEX(PLAN_DESARROLLO!$E:$E,MATCH($C31,PLAN_DESARROLLO!$A:$A,0))) -> Realizar la construcción de 200 metros lineales de red de acueducto en el municipio | H31: 0 | I31: 0 | J31: =IF(OR($H31="",$I31=""),"",IFERROR($I31/$H31,0)) -> 0 | K31: 0 | L31: 0 | M31: =IF(OR($K31="",$L31=""),"",IFERROR($L31/$K31,0)) -> 0 | T31: =IF($A31="","",TODAY()) -> 46059
A32: 2024 | B32: Secretaría de Planeación y Obras Públicas | C32: META-090 | D32: =IF($C32="","",INDEX(PLAN_DESARROLLO!$B:$B,MATCH($C32,PLAN_DESARROLLO!$A:$A,0))) -> 2024257770017 | E32: =IF($C32="","",INDEX(PLAN_DESARROLLO!$C:$C,MATCH($C32,PLAN_DESARROLLO!$A:$A,0))) -> POR EL SUPATÁ SOÑADO AVANZAMOS JUNTOS EN LA LÍNEA ESTRATÉGICA SOCIAL | F32: =IF($C32="","",INDEX(PLAN_DESARROLLO!$D:$D,MATCH($C32,PLAN_DESARROLLO!$A:$A,0))) -> A.P.S.B | G32: =IF($C32="","",INDEX(PLAN_DESARROLLO!$E:$E,MATCH($C32,PLAN_DESARROLLO!$A:$A,0))) -> Transferir anualmente al Plan Departamental de Aguas -PDA- los recursos comprometidos a través de Acuerdo Municipal en el cuatrienio. | H32: 1 | I32: 1 | J32: =IF(OR($H32="",$I32=""),"",IFERROR($I32/$H32,0)) -> 1 | K32: 442578049 | L32: 442578049 | M32: =IF(OR($K32="",$L32=""),"",IFERROR($L32/$K32,0)) -> 1 | N32: Transferencia del 60% del toral de los recursos de APSB al PDA vigencia 2024 | O32: SGP - APSB | P32: Cumplida | Q32: Certificación | T32: =IF($A32="","",TODAY()) -> 46059
A33: 2025 | B33: Secretaría de Planeación y Obras Públicas | C33: META-090 | D33: =IF($C33="","",INDEX(PLAN_DESARROLLO!$B:$B,MATCH($C33,PLAN_DESARROLLO!$A:$A,0))) -> 2024257770017 | E33: =IF($C33="","",INDEX(PLAN_DESARROLLO!$C:$C,MATCH($C33,PLAN_DESARROLLO!$A:$A,0))) -> POR EL SUPATÁ SOÑADO AVANZAMOS JUNTOS EN LA LÍNEA ESTRATÉGICA SOCIAL | F33: =IF($C33="","",INDEX(PLAN_DESARROLLO!$D:$D,MATCH($C33,PLAN_DESARROLLO!$A:$A,0))) -> A.P.S.B | G33: =IF($C33="","",INDEX(PLAN_DESARROLLO!$E:$E,MATCH($C33,PLAN_DESARROLLO!$A:$A,0))) -> Transferir anualmente al Plan Departamental de Aguas -PDA- los recursos comprometidos a través de Acuerdo Municipal en el cuatrienio. | H33: 1 | I33: 1 | J33: =IF(OR($H33="",$I33=""),"",IFERROR($I33/$H33,0)) -> 1 | K33: 5.5332459e+08 | L33: 5.5332459e+08 | M33: =IF(OR($K33="",$L33=""),"",IFERROR($L33/$K33,0)) -> 1 | N33: Transferencia del 60% del toral de los recursos de APSB al PDA vigencia 2025 | O33: SGP - APSB | P33: Cumplida | Q33: Certificación | T33: =IF($A33="","",TODAY()) -> 46059
A34: 2024 | B34: Secretaría de Planeación y Obras Públicas | C34: META-091 | D34: =IF($C34="","",INDEX(PLAN_DESARROLLO!$B:$B,MATCH($C34,PLAN_DESARROLLO!$A:$A,0))) -> 2024257770017 | E34: =IF($C34="","",INDEX(PLAN_DESARROLLO!$C:$C,MATCH($C34,PLAN_DESARROLLO!$A:$A,0))) -> POR EL SUPATÁ SOÑADO AVANZAMOS JUNTOS EN LA LÍNEA ESTRATÉGICA SOCIAL | F34: =IF($C34="","",INDEX(PLAN_DESARROLLO!$D:$D,MATCH($C34,PLAN_DESARROLLO!$A:$A,0))) -> A.P.S.B | G34: =IF($C34="","",INDEX(PLAN_DESARROLLO!$E:$E,MATCH($C34,PLAN_DESARROLLO!$A:$A,0))) -> Realizar anulmente doce (12) analisis de calidad del agua de acuerdo a la resolucion 2115 de 2007 | H34: 12 | I34: 7 | J34: =IF(OR($H34="",$I34=""),"",IFERROR($I34/$H34,0)) -> 0.58333333 | K34: 8554315 | L34: 8554315 | M34: =IF(OR($K34="",$L34=""),"",IFERROR($L34/$K34,0)) -> 1 | N34: Contrato de Prestacion de Servicios No. CPS-093-2024 Cuyo objeto fue realizar las muestras y análisis de calidad de agua suministrada por el acueducto urbano, garantizando así un suministro de agua apta para consumo humano | O34: Recursos Propios | P34: Cumplida | Q34: Informe | T34: =IF($A34="","",TODAY()) -> 46059
A35: 2025 | B35: Secretaría de Planeación y Obras Públicas | C35: META-091 | D35: =IF($C35="","",INDEX(PLAN_DESARROLLO!$B:$B,MATCH($C35,PLAN_DESARROLLO!$A:$A,0))) -> 2024257770017 | E35: =IF($C35="","",INDEX(PLAN_DESARROLLO!$C:$C,MATCH($C35,PLAN_DESARROLLO!$A:$A,0))) -> POR EL SUPATÁ SOÑADO AVANZAMOS JUNTOS EN LA LÍNEA ESTRATÉGICA SOCIAL | F35: =IF($C35="","",INDEX(PLAN_DESARROLLO!$D:$D,MATCH($C35,PLAN_DESARROLLO!$A:$A,0))) -> A.P.S.B | G35: =IF($C35="","",INDEX(PLAN_DESARROLLO!$E:$E,MATCH($C35,PLAN_DESARROLLO!$A:$A,0))) -> Realizar anulmente doce (12) analisis de calidad del agua de acuerdo a la resolucion 2115 de 2007 | H35: 12 | I35: 12 | J35: =IF(OR($H35="",$I35=""),"",IFERROR($I35/$H35,0)) -> 1 | K35: 8827420 | L35: 8827420 | M35: =IF(OR($K35="",$L35=""),"",IFERROR($L35/$K35,0)) -> 1 | N35: Contrato de Prestacion de Servicios No. CPS-079-2025 Prestacion de servicios para la toma y analisis de agua potable en el sistema de acueducto urbano del municipio de supata cundinamarca. | O35: Recursos Propios | P35: Cumplida | Q35: Informe | T35: =IF($A35="","",TODAY()) -> 46059
A36: 2024 | B36: Secretaría de Planeación y Obras Públicas | C36: META-092 | D36: =IF($C36="","",INDEX(PLAN_DESARROLLO!$B:$B,MATCH($C36,PLAN_DESARROLLO!$A:$A,0))) -> 2024257770017 | E36: =IF($C36="","",INDEX(PLAN_DESARROLLO!$C:$C,MATCH($C36,PLAN_DESARROLLO!$A:$A,0))) -> POR EL SUPATÁ SOÑADO AVANZAMOS JUNTOS EN LA LÍNEA ESTRATÉGICA SOCIAL | F36: =IF($C36="","",INDEX(PLAN_DESARROLLO!$D:$D,MATCH($C36,PLAN_DESARROLLO!$A:$A,0))) -> A.P.S.B | G36: =IF($C36="","",INDEX(PLAN_DESARROLLO!$E:$E,MATCH($C36,PLAN_DESARROLLO!$A:$A,0))) -> elaborar el programa de Uso Eficiente y Ahorro del Agua (PUEAA) en el municipio durante el cuatrienio | H36: 1 | I36: 1 | J36: =IF(OR($H36="",$I36=""),"",IFERROR($I36/$H36,0)) -> 1 | K36: 34900000 | L36: 34900000 | M36: =IF(OR($K36="",$L36=""),"",IFERROR($L36/$K36,0)) -> 1 | N36: Contrato de Prestacion de Servicios No. CPS-135-2024 con el cual se elaboró el Plan de Uso Eficiente y Ahorro del Agua – PUEAA para el acueducto urbano | O36: SGP - APSB | P36: Cumplida | Q36: Informe | T36: =IF($A36="","",TODAY()) -> 46059
A37: 2025 | B37: Secretaría de Planeación y Obras Públicas | C37: META-092 | D37: =IF($C37="","",INDEX(PLAN_DESARROLLO!$B:$B,MATCH($C37,PLAN_DESARROLLO!$A:$A,0))) -> 2024257770017 | E37: =IF($C37="","",INDEX(PLAN_DESARROLLO!$C:$C,MATCH($C37,PLAN_DESARROLLO!$A:$A,0))) -> POR EL SUPATÁ SOÑADO AVANZAMOS JUNTOS EN LA LÍNEA ESTRATÉGICA SOCIAL | F37: =IF($C37="","",INDEX(PLAN_DESARROLLO!$D:$D,MATCH($C37,PLAN_DESARROLLO!$A:$A,0))) -> A.P.S.B | G37: =IF($C37="","",INDEX(PLAN_DESARROLLO!$E:$E,MATCH($C37,PLAN_DESARROLLO!$A:$A,0))) -> elaborar el programa de Uso Eficiente y Ahorro del Agua (PUEAA) en el municipio durante el cuatrienio | H37: 0 | I37: 0 | J37: =IF(OR($H37="",$I37=""),"",IFERROR($I37/$H37,0)) -> 0 | K37: 0 | L37: 0 | M37: =IF(OR($K37="",$L37=""),"",IFERROR($L37/$K37,0)) -> 0 | T37: =IF($A37="","",TODAY()) -> 46059
A38: 2024 | B38: Secretaría de Planeación y Obras Públicas | C38: META-093 | D38: =IF($C38="","",INDEX(PLAN_DESARROLLO!$B:$B,MATCH($C38,PLAN_DESARROLLO!$A:$A,0))) -> 2024257770017 | E38: =IF($C38="","",INDEX(PLAN_DESARROLLO!$C:$C,MATCH($C38,PLAN_DESARROLLO!$A:$A,0))) -> POR EL SUPATÁ SOÑADO AVANZAMOS JUNTOS EN LA LÍNEA ESTRATÉGICA SOCIAL | F38: =IF($C38="","",INDEX(PLAN_DESARROLLO!$D:$D,MATCH($C38,PLAN_DESARROLLO!$A:$A,0))) -> A.P.S.B | G38: =IF($C38="","",INDEX(PLAN_DESARROLLO!$E:$E,MATCH($C38,PLAN_DESARROLLO!$A:$A,0))) -> Acompañamiento para la legalizacion de acueductos veredales con requisitos minimos | H38: 1 | I38: 2 | J38: =IF(OR($H38="",$I38=""),"",IFERROR($I38/$H38,0)) -> 2 | K38: 0 | L38: 0 | M38: =IF(OR($K38="",$L38=""),"",IFERROR($L38/$K38,0)) -> 0 | N38: Se realizo acompañamiento al Acueducto la Cabrera y Acueducto Regional de las veredas Santa Rosa, Providencia, Cristales y Mesitas, permitiendoles así participar en la convocatoria de Agua a la Vereda de EPC saliendo beneficiados de este programa | P38: Cumplida | Q38: Informe | T38: =IF($A38="","",TODAY()) -> 46059
A39: 2025 | B39: Secretaría de Planeación y Obras Públicas | C39: META-093 | D39: =IF($C39="","",INDEX(PLAN_DESARROLLO!$B:$B,MATCH($C39,PLAN_DESARROLLO!$A:$A,0))) -> 2024257770017 | E39: =IF($C39="","",INDEX(PLAN_DESARROLLO!$C:$C,MATCH($C39,PLAN_DESARROLLO!$A:$A,0))) -> POR EL SUPATÁ SOÑADO AVANZAMOS JUNTOS EN LA LÍNEA ESTRATÉGICA SOCIAL | F39: =IF($C39="","",INDEX(PLAN_DESARROLLO!$D:$D,MATCH($C39,PLAN_DESARROLLO!$A:$A,0))) -> A.P.S.B | G39: =IF($C39="","",INDEX(PLAN_DESARROLLO!$E:$E,MATCH($C39,PLAN_DESARROLLO!$A:$A,0))) -> Acompañamiento para la legalizacion de acueductos veredales con requisitos minimos | H39: 1 | I39: 1 | J39: =IF(OR($H39="",$I39=""),"",IFERROR($I39/$H39,0)) -> 1 | K39: 0 | L39: 0 | M39: =IF(OR($K39="",$L39=""),"",IFERROR($L39/$K39,0)) -> 0 | N39: Se realizo acompañamiento al Acueducto de Monte Dulce permitiendole participar en la convocatoria de Agua a la Vereda de EPC saliendo beneficiado de este programa | P39: Cumplida | Q39: Informe | T39: =IF($A39="","",TODAY()) -> 46059
A40: 2024 | B40: Secretaría de Planeación y Obras Públicas | C40: META-094 | D40: =IF($C40="","",INDEX(PLAN_DESARROLLO!$B:$B,MATCH($C40,PLAN_DESARROLLO!$A:$A,0))) -> 2024257770017 | E40: =IF($C40="","",INDEX(PLAN_DESARROLLO!$C:$C,MATCH($C40,PLAN_DESARROLLO!$A:$A,0))) -> POR EL SUPATÁ SOÑADO AVANZAMOS JUNTOS EN LA LÍNEA ESTRATÉGICA SOCIAL | F40: =IF($C40="","",INDEX(PLAN_DESARROLLO!$D:$D,MATCH($C40,PLAN_DESARROLLO!$A:$A,0))) -> A.P.S.B | G40: =IF($C40="","",INDEX(PLAN_DESARROLLO!$E:$E,MATCH($C40,PLAN_DESARROLLO!$A:$A,0))) -> implementacion de un programa de micromedicion en el area urbana | H40: 1 | I40: 1 | J40: =IF(OR($H40="",$I40=""),"",IFERROR($I40/$H40,0)) -> 1 | K40: 19665552 | L40: 19665552 | M40: =IF(OR($K40="",$L40=""),"",IFERROR($L40/$K40,0)) -> 1 | N40: Acta de aceptacion de oferta proceso de selección MC 032-2024 Contrato de Compra No. COM-010-2024 Compra de equipos de micromedicion de agua potable en el marco de la implementacion de un programa de micromedicion en el acuedcuto urbano del Municipio de Supatá Cundinamarca. | O40: SGP - APSB | P40: Cumplida | Q40: Informe | T40: =IF($A40="","",TODAY()) -> 46059
A41: 2025 | B41: Secretaría de Planeación y Obras Públicas | C41: META-094 | D41: =IF($C41="","",INDEX(PLAN_DESARROLLO!$B:$B,MATCH($C41,PLAN_DESARROLLO!$A:$A,0))) -> 2024257770017 | E41: =IF($C41="","",INDEX(PLAN_DESARROLLO!$C:$C,MATCH($C41,PLAN_DESARROLLO!$A:$A,0))) -> POR EL SUPATÁ SOÑADO AVANZAMOS JUNTOS EN LA LÍNEA ESTRATÉGICA SOCIAL | F41: =IF($C41="","",INDEX(PLAN_DESARROLLO!$D:$D,MATCH($C41,PLAN_DESARROLLO!$A:$A,0))) -> A.P.S.B | G41: =IF($C41="","",INDEX(PLAN_DESARROLLO!$E:$E,MATCH($C41,PLAN_DESARROLLO!$A:$A,0))) -> implementacion de un programa de micromedicion en el area urbana | H41: 1 | I41: 0 | J41: =IF(OR($H41="",$I41=""),"",IFERROR($I41/$H41,0)) -> 0 | K41: 0 | L41: 0 | M41: =IF(OR($K41="",$L41=""),"",IFERROR($L41/$K41,0)) -> 0 | T41: =IF($A41="","",TODAY()) -> 46059
A42: 2024 | B42: Secretaría de Planeación y Obras Públicas | C42: META-095 | D42: =IF($C42="","",INDEX(PLAN_DESARROLLO!$B:$B,MATCH($C42,PLAN_DESARROLLO!$A:$A,0))) -> 2024257770017 | E42: =IF($C42="","",INDEX(PLAN_DESARROLLO!$C:$C,MATCH($C42,PLAN_DESARROLLO!$A:$A,0))) -> POR EL SUPATÁ SOÑADO AVANZAMOS JUNTOS EN LA LÍNEA ESTRATÉGICA SOCIAL | F42: =IF($C42="","",INDEX(PLAN_DESARROLLO!$D:$D,MATCH($C42,PLAN_DESARROLLO!$A:$A,0))) -> A.P.S.B | G42: =IF($C42="","",INDEX(PLAN_DESARROLLO!$E:$E,MATCH($C42,PLAN_DESARROLLO!$A:$A,0))) -> Realizar anulmente el fortalecimiento para el reporte de la informacion de las entidades de control | H42: 1 | I42: 1 | J42: =IF(OR($H42="",$I42=""),"",IFERROR($I42/$H42,0)) -> 1 | K42: 14700000 | L42: 14700000 | M42: =IF(OR($K42="",$L42=""),"",IFERROR($L42/$K42,0)) -> 1 | N42: Contrato de Prestacion de Servicios No. CPS-091-2024 Cuyo objeto fue Servicios profesionales deasesoria para el fortalecimiento en el reporte de la informacion orientada al cumplimiento de la regulacion y normatividad vigente en materia de agua potable y saneamiento basico de la oficina de servicios publicos del Municipio de Supatá | O42: Recursos Propios | P42: Cumplida | Q42: Informe | T42: =IF($A42="","",TODAY()) -> 46059
A43: 2025 | B43: Secretaría de Planeación y Obras Públicas | C43: META-095 | D43: =IF($C43="","",INDEX(PLAN_DESARROLLO!$B:$B,MATCH($C43,PLAN_DESARROLLO!$A:$A,0))) -> 2024257770017 | E43: =IF($C43="","",INDEX(PLAN_DESARROLLO!$C:$C,MATCH($C43,PLAN_DESARROLLO!$A:$A,0))) -> POR EL SUPATÁ SOÑADO AVANZAMOS JUNTOS EN LA LÍNEA ESTRATÉGICA SOCIAL | F43: =IF($C43="","",INDEX(PLAN_DESARROLLO!$D:$D,MATCH($C43,PLAN_DESARROLLO!$A:$A,0))) -> A.P.S.B | G43: =IF($C43="","",INDEX(PLAN_DESARROLLO!$E:$E,MATCH($C43,PLAN_DESARROLLO!$A:$A,0))) -> Realizar anulmente el fortalecimiento para el reporte de la informacion de las entidades de control | H43: 1 | I43: 1 | J43: =IF(OR($H43="",$I43=""),"",IFERROR($I43/$H43,0)) -> 1 | K43: 25080000 | L43: 25080000 | M43: =IF(OR($K43="",$L43=""),"",IFERROR($L43/$K43,0)) -> 1 | N43: Contrato de Prestacion de Servicios No. CPS-045-2025. Prestar los servicios profesionales de asesoria para el fortalecimiento en el reporte de información orientado al cumplimiento de la regulación y normatividad vigente en materia de agua potable y saneamiento basico de la oficina de servicios publicos del Municipio de Supatá Cundinamarca, conforme a los lineamientos establecidos en el plan de desarrollo municipal | O43: Recursos Propios | P43: Cumplida | Q43: Informe | T43: =IF($A43="","",TODAY()) -> 46059
A44: 2024 | B44: Secretaría de Planeación y Obras Públicas | C44: META-096 | D44: =IF($C44="","",INDEX(PLAN_DESARROLLO!$B:$B,MATCH($C44,PLAN_DESARROLLO!$A:$A,0))) -> 2024257770017 | E44: =IF($C44="","",INDEX(PLAN_DESARROLLO!$C:$C,MATCH($C44,PLAN_DESARROLLO!$A:$A,0))) -> POR EL SUPATÁ SOÑADO AVANZAMOS JUNTOS EN LA LÍNEA ESTRATÉGICA SOCIAL | F44: =IF($C44="","",INDEX(PLAN_DESARROLLO!$D:$D,MATCH($C44,PLAN_DESARROLLO!$A:$A,0))) -> A.P.S.B | G44: =IF($C44="","",INDEX(PLAN_DESARROLLO!$E:$E,MATCH($C44,PLAN_DESARROLLO!$A:$A,0))) -> Actualizar el Plan de Saneamiento y Manejo de Vertimientos (PSMV) | H44: 1 | I44: 0 | J44: =IF(OR($H44="",$I44=""),"",IFERROR($I44/$H44,0)) -> 0 | K44: 0 | L44: 0 | M44: =IF(OR($K44="",$L44=""),"",IFERROR($L44/$K44,0)) -> 0 | T44: =IF($A44="","",TODAY()) -> 46059
...
